

<mujoco model="tendon">
	<!-- diy robosuite model -->
	<!-- https://docs.google.com/document/d/1bSUKkpjmbKqWyV5Oc7_4VL4FGKAQZx8aWm_nvlmTVmE/edit?pli=1&tab=t.0 -->
    <actuator>
	<motor name="torq_j1" joint="joint_1" ctrlrange="0 1" ctrllimited="true" gear="10 0"/>
	<motor name="torq_j2" joint="joint_2" ctrlrange="0 1" ctrllimited="true" gear="10 0"/>
	<motor name="torq_j3" joint="joint_3" ctrlrange="0 1" ctrllimited="true" gear="10 0"/>
	<motor name="torq_j4" joint="joint_4" ctrlrange="0 1" ctrllimited="true" gear="10 0"/>
	<motor name="torq_j5" joint="joint_5" ctrlrange="0 1" ctrllimited="true" gear="10 0"/>
	<motor name="torq_j6" joint="joint_6" ctrlrange="0 1" ctrllimited="true" gear="10 0"/>
    </actuator>


	<asset>
		<mesh name="base" file="./meshes/base.STL" scale="1 1 1"/>
		<mesh name="s1" file="./meshes/s1.STL" scale="1 1 1"/>
		<mesh name="s2" file="./meshes/s1.STL" scale="1 1 1"/>
		<mesh name="s3" file="./meshes/s1.STL" scale="1 1 1"/>
		<mesh name="s4" file="./meshes/s1.STL" scale="1 1 1"/>
		<mesh name="s5" file="./meshes/s1.STL" scale="1 1 1"/>
		<mesh name="s6" file="./meshes/s1.STL" scale="1 1 1"/>
		<mesh name="s7" file="./meshes/s1.STL" scale="1 1 1"/>
		<mesh name="s8" file="./meshes/s1.STL" scale="1 1 1"/>
		<mesh name="s9" file="./meshes/s1.STL" scale="1 1 1"/>
		<mesh name="s10" file="./meshes/s1.STL" scale="1 1 1"/>

	</asset>



    <!-- <option timestep="0.002" tolerance="1e-10" jacobian="dense" gravity="0 0 -0.981" /> -->

    <option timestep="0.002" tolerance="1e-10" jacobian="dense" gravity="0 0 0" />


    <worldbody>
		<site name="waypoint" type="sphere" size="0.005" pos="-1 -1 -1" rgba=".8 .8 .8 1" />

    	<body name="base" pos="0 0 0">
			<!-- robot view -->
			<camera mode="fixed" name="robotview" pos="-0.25 -0.6 0.2" quat="0.61237244 0.35355339 -0.61237244 0.35355339"/>
			<!-- base mesh and visual -->
			<geom mesh="base" pos="0.0000 0.0000 0.0000" type="mesh" group="1" />
			<!-- <inertial diaginertia="0 0 0" mass="100" pos="0.05 0  -0.1"/> -->

			<!-- tendon for each wire -->
			<body>
				<geom type="sphere" pos="0.02028   0.00544 -0.15" size="0.005"/>
				<joint name="joint_1" type="slide" axis="0 0 -1" damping='0.1'  limited="true" range="-.1 .1"/>
				<site name="end_1" pos="0.02028   0.00544 -0.15"/>
			</body>

			<body>
				<geom type="sphere" pos="0.02028  -0.00544 -0.15" size="0.005"/>
				<joint name="joint_2" type="slide" axis="0 0 -1" damping='0.1' limited="true" range="-.1 .1"/>
				<site name="end_2" pos="0.02028  -0.00544 -0.15"/>
			</body>

			<body >
				<geom type="sphere" pos="-0.00544 -0.02028 -0.15" size="0.005"/>
				<joint name="joint_3" type="slide" axis="0 0 -1" damping='0.1' limited="true" range="-.1 .1"/>
				<site name="end_3" pos="-0.00544 -0.02028 -0.15"/>
			</body>

			<body >
				<geom type="sphere" pos="-0.01485 -0.01485 -0.15" size="0.005"/>
				<joint name="joint_4" type="slide" axis="0 0 -1" damping='0.1' limited="true" range="-.1 .1"/>
				<site name="end_4" pos="-0.01485 -0.01485 -0.15"/>
			</body>

			<body >
				<geom type="sphere" pos="-0.01485  0.01485 -0.15" size="0.005"/>
				<joint name="joint_5" type="slide" axis="0 0 -1" damping='0.1' limited="true" range="-.1 .1"/>
				<site name="end_5" pos="-0.01485  0.01485 -0.15"/>
			</body>

			<body >
				<geom type="sphere" pos="-0.00544  0.02028 -0.15" size="0.005"/>
				<joint name="joint_6" type="slide" axis="0 0 -1" damping='0.1' limited="true" range="-.1 .1"/>
				<site name="end_6" pos="-0.00544  0.02028 -0.15"/>
			</body>

			<!-- tendon body geom -->
			<body name="s1">
			<geom type="sphere" pos="0 0 0.0000" size="0.005"  rgba=".8 .2 .1 1"/>
			<!-- <joint type="hinge" pos="0 0 0.0000" axis="1 0 0"  damping="1.0000" stiffness="0.50"/>
			<joint type="hinge" pos="0 0 0.0000" axis="0 1 0"  damping="1.0000" stiffness="0.50"/> -->
			<geom mesh="s1" pos="0 0.0000 0.0000" type="mesh" group="1" name="s1_vis" />
			<geom mesh="s1" pos="0 0.0000 0.0000" type="mesh" group="0" name="s1_col" contype="1" conaffinity="1"/>
			<site name="s_1_1" pos="0.02028   0.00544  -0.0000" size="0.002"/>
			<site name="s_1_2" pos="0.02028  -0.00544  -0.0000" size="0.002"/>
			<site name="s_1_3" pos="-0.00544 -0.02028  -0.0000" size="0.002"/>
			<site name="s_1_4" pos="-0.01485 -0.01485  -0.0000" size="0.002"/>
			<site name="s_1_5" pos="-0.01485  0.01485  -0.0000" size="0.002"/>
			<site name="s_1_6" pos="-0.00544  0.02028  -0.0000" size="0.002"/>	


			<body name="s2">
			<geom type="sphere" pos="0 0 0.050" size="0.005"  rgba=".8 .2 .1 1"/>
			<joint type="hinge" pos="0 0 0.050" axis="1 0 0"  damping="1.0000" stiffness="0.50"/>
			<joint type="hinge" pos="0 0 0.050" axis="0 1 0"  damping="1.0000" stiffness="0.50"/>
			<geom mesh="s2" pos="0 0.0000 0.050" type="mesh" group="1" name="s2_vis" />
			<geom mesh="s2" pos="0 0.0000 0.050" type="mesh" group="0" name="s2_col" contype="1" conaffinity="1"/>
			<site name="s_2_1" pos="0.02028   0.00544  0.0500" size="0.002"/>
			<site name="s_2_2" pos="0.02028  -0.00544  0.0500" size="0.002"/>
			<site name="s_2_3" pos="-0.00544 -0.02028  0.0500" size="0.002"/>
			<site name="s_2_4" pos="-0.01485 -0.01485  0.0500" size="0.002"/>
			<site name="s_2_5" pos="-0.01485  0.01485  0.0500" size="0.002"/>
			<site name="s_2_6" pos="-0.00544  0.02028  0.0500" size="0.002"/>
			
			
			<body name="s3">
			<geom type="sphere" pos="0 0 0.100" size="0.005"  rgba=".8 .2 .1 1"/>
			<joint type="hinge" pos="0 0 0.100" axis="1 0 0"  damping="1.0000" stiffness="0.50"/>
			<joint type="hinge" pos="0 0 0.100" axis="0 1 0"  damping="1.0000" stiffness="0.50"/>
			<geom mesh="s3" pos="0 0.0000 0.100" type="mesh" group="1" name="s3_vis" />
			<geom mesh="s3" pos="0 0.0000 0.100" type="mesh" group="0" name="s3_col" contype="1" conaffinity="1"/>
			<site name="s_3_1" pos="0.02028   0.00544  0.1000" size="0.002"/>
			<site name="s_3_2" pos="0.02028  -0.00544  0.1000" size="0.002"/>
			<site name="s_3_3" pos="-0.00544 -0.02028  0.1000" size="0.002"/>
			<site name="s_3_4" pos="-0.01485 -0.01485  0.1000" size="0.002"/>
			<site name="s_3_5" pos="-0.01485  0.01485  0.1000" size="0.002"/>
			<site name="s_3_6" pos="-0.00544  0.02028  0.1000" size="0.002"/>
			
			<body name="s4">
			<geom type="sphere" pos="0 0 0.150" size="0.005"  rgba=".8 .2 .1 1"/>
			<joint type="hinge" pos="0 0 0.150" axis="1 0 0"  damping="1.0000" stiffness="0.50"/>
			<joint type="hinge" pos="0 0 0.150" axis="0 1 0"  damping="1.0000" stiffness="0.50"/>
			<geom mesh="s4" pos="0 0.0000 0.150" type="mesh" group="1" name="s4_vis" />
			<geom mesh="s4" pos="0 0.0000 0.150" type="mesh" group="0" name="s4_col" contype="1" conaffinity="1"/>
			<site name="s_4_1" pos="0.02028   0.00544  0.1500" size="0.002"/>
			<site name="s_4_2" pos="0.02028  -0.00544  0.1500" size="0.002"/>
			<site name="s_4_3" pos="-0.00544 -0.02028  0.1500" size="0.002"/>
			<site name="s_4_4" pos="-0.01485 -0.01485  0.1500" size="0.002"/>
			<site name="s_4_5" pos="-0.01485  0.01485  0.1500" size="0.002"/>
			<site name="s_4_6" pos="-0.00544  0.02028  0.1500" size="0.002"/>
			
			<body name="s5">
			<geom type="sphere" pos="0 0 0.200" size="0.005"  rgba=".8 .2 .1 1"/>
			<joint type="hinge" pos="0 0 0.200" axis="1 0 0"  damping="1.0000" stiffness="0.50"/>
			<joint type="hinge" pos="0 0 0.200" axis="0 1 0"  damping="1.0000" stiffness="0.50"/>
			<geom mesh="s5" pos="0 0.0000 0.200" type="mesh" group="1" name="s5_vis" />
			<geom mesh="s5" pos="0 0.0000 0.200" type="mesh" group="0" name="s5_col" contype="1" conaffinity="1"/>
			<site name="s_5_1" pos="0.02028   0.00544  0.2000" size="0.002"/>
			<site name="s_5_2" pos="0.02028  -0.00544  0.2000" size="0.002"/>
			<site name="s_5_3" pos="-0.00544 -0.02028  0.2000" size="0.002"/>
			<site name="s_5_4" pos="-0.01485 -0.01485  0.2000" size="0.002"/>
			<site name="s_5_5" pos="-0.01485  0.01485  0.2000" size="0.002"/>
			<site name="s_5_6" pos="-0.00544  0.02028  0.2000" size="0.002"/>
			
			<body name="s6">
			<geom type="sphere" pos="0 0 0.250" size="0.005"  rgba=".8 .2 .1 1"/>
			<joint type="hinge" pos="0 0 0.250" axis="1 0 0"  damping="1.0000" stiffness="0.50"/>
			<joint type="hinge" pos="0 0 0.250" axis="0 1 0"  damping="1.0000" stiffness="0.50"/>
			<geom mesh="s6" pos="0 0.0000 0.250" type="mesh"  group="1" name="s6_vis" />
			<geom mesh="s6" pos="0 0.0000 0.250" type="mesh"  group="0" name="s6_col" contype="1" conaffinity="1"/>
			<site name="s_6_1" pos="0.02028   0.00544  0.2500" size="0.002"/>
			<site name="s_6_2" pos="0.02028  -0.00544  0.2500" size="0.002"/>
			<site name="s_6_3" pos="-0.00544 -0.02028  0.2500" size="0.002"/>
			<site name="s_6_4" pos="-0.01485 -0.01485  0.2500" size="0.002"/>
			<site name="s_6_5" pos="-0.01485  0.01485  0.2500" size="0.002"/>
			<site name="s_6_6" pos="-0.00544  0.02028  0.2500" size="0.002"/>

			<body name="s7">
			<geom type="sphere" pos="0 0 0.300" size="0.005"  rgba=".8 .2 .1 1"/>
			<joint type="hinge" pos="0 0 0.300" axis="1 0 0"  damping="1.0000" stiffness="0.50"/>
			<joint type="hinge" pos="0 0 0.300" axis="0 1 0"  damping="1.0000" stiffness="0.50"/>
			<geom mesh="s7" pos="0 0.0000 0.300" type="mesh"  group="1" name="s7_vis" />
			<geom mesh="s7" pos="0 0.0000 0.300" type="mesh"  group="0" name="s7_col" contype="1" conaffinity="1"/>
			<site name="s_7_1" pos="0.02028   0.00544  0.3000" size="0.002"/>
			<site name="s_7_2" pos="0.02028  -0.00544  0.3000" size="0.002"/>
			<site name="s_7_3" pos="-0.00544 -0.02028  0.3000" size="0.002"/>
			<site name="s_7_4" pos="-0.01485 -0.01485  0.3000" size="0.002"/>
			<site name="s_7_5" pos="-0.01485  0.01485  0.3000" size="0.002"/>
			<site name="s_7_6" pos="-0.00544  0.02028  0.3000" size="0.002"/>


			<body name="s8">
			<geom type="sphere" pos="0 0 0.350" size="0.005"  rgba=".8 .2 .1 1"/>
			<joint type="hinge" pos="0 0 0.350" axis="1 0 0"  damping="1.0000" stiffness="0.50"/>
			<joint type="hinge" pos="0 0 0.350" axis="0 1 0"  damping="1.0000" stiffness="0.50"/>
			<geom mesh="s8" pos="0 0.0000 0.350" type="mesh"  group="1" name="s8_vis" />
			<geom mesh="s8" pos="0 0.0000 0.350" type="mesh"  group="0" name="s8_col" contype="1" conaffinity="1"/>
			<site name="s_8_1" pos="0.02028   0.00544  0.3500" size="0.002"/>
			<site name="s_8_2" pos="0.02028  -0.00544  0.3500" size="0.002"/>
			<site name="s_8_3" pos="-0.00544 -0.02028  0.3500" size="0.002"/>
			<site name="s_8_4" pos="-0.01485 -0.01485  0.3500" size="0.002"/>
			<site name="s_8_5" pos="-0.01485  0.01485  0.3500" size="0.002"/>
			<site name="s_8_6" pos="-0.00544  0.02028  0.3500" size="0.002"/>


			<body name="s9">
			<geom type="sphere" pos="0 0 0.400" size="0.005"  rgba=".8 .2 .1 1"/>
			<joint type="hinge" pos="0 0 0.400" axis="1 0 0"  damping="1.0000" stiffness="0.50"/>
			<joint type="hinge" pos="0 0 0.400" axis="0 1 0"  damping="1.0000" stiffness="0.50"/>
			<geom mesh="s9" pos="0 0.0000 0.400" type="mesh" group="1" name="s9_vis" />
			<geom mesh="s9" pos="0 0.0000 0.400" type="mesh" group="0" name="s9_col" contype="1" conaffinity="1"/>
			<site name="s_9_1" pos="0.02028   0.00544  0.4000" size="0.002"/>
			<site name="s_9_2" pos="0.02028  -0.00544  0.4000" size="0.002"/>
			<site name="s_9_3" pos="-0.00544 -0.02028  0.4000" size="0.002"/>
			<site name="s_9_4" pos="-0.01485 -0.01485  0.4000" size="0.002"/>
			<site name="s_9_5" pos="-0.01485  0.01485  0.4000" size="0.002"/>
			<site name="s_9_6" pos="-0.00544  0.02028  0.4000" size="0.002"/>

			<body name="s10">
			<geom type="sphere" pos="0 0 0.450" size="0.005"  rgba=".8 .2 .1 1"/>
			<joint type="hinge" pos="0 0 0.450" axis="1 0 0"  damping="1.0000" stiffness="0.50"/>
			<joint type="hinge" pos="0 0 0.450" axis="0 1 0"  damping="1.0000" stiffness="0.50"/>
			<geom mesh="s10" pos="0 0.0000 0.450" type="mesh" group="1" name="s10_vis" />
			<geom mesh="s10" pos="0 0.0000 0.450" type="mesh" group="0" name="s10_col" contype="1" conaffinity="1"/>
			<site name="s_10_1" pos="0.02028   0.00544  0.4500" size="0.002"/>
			<site name="s_10_2" pos="0.02028  -0.00544  0.4500" size="0.002"/>
			<site name="s_10_3" pos="-0.00544 -0.02028  0.4500" size="0.002"/>
			<site name="s_10_4" pos="-0.01485 -0.01485  0.4500" size="0.002"/>
			<site name="s_10_5" pos="-0.01485  0.01485  0.4500" size="0.002"/>
			<site name="s_10_6" pos="-0.00544  0.02028  0.4500" size="0.002"/>

			
			<!-- virtual hand  -->
			<!-- pos ,quat should be algin to the real robot -->
			<body name="right_hand" pos="0 0 0.50" quat="1 0 0 0">			
				<geom type="sphere" pos="0 0 0.50" size="0.005"  rgba=".8 .2 .1 1"/>

				<!-- This sites were added for visualization. They are all standardized between models-->
				<!-- Position mimics the gripper attachment point (right_hand) -->
				<!--  Y-axis should be perpendicular to grasping motion, and Z-axis should point out of the robot eef -->
				<site name="ee" pos="0 0 0" size="0.01 0.01 0.01" rgba="0 0 1 1" type="sphere" group="1"/>
				<site name="ee_x" pos="0 0 0" size="0.005 .1"  rgba="1 0 0 0" type="cylinder" group="1"/>
				<site name="ee_z" pos="0 0 0" size="0.005 .1"  rgba="0 0 1 0" type="cylinder" group="1"/>
				<site name="ee_y" pos="0 0 0" size="0.005 .1"  rgba="0 1 0 0" type="cylinder" group="1"/>
				<!-- This camera points out from the eef. -->
				<camera mode="fixed" name="eye_in_hand" pos="0.05 0 0" quat="0 0.707108 0.707108 0" fovy="75"/>
				<!-- To add gripper -->
			</body>
			</body>
			</body>
			</body>
			</body>
			</body>
			</body>
			</body>
			</body>
			</body>
			</body>
		</body>
		</worldbody>
	
    <tendon>
	
		<spatial width="0.002" limited="true" range="0.45 0.55">
		<site site="end_1"/>
		<site site="s_1_1"/>
		<site site="s_2_1"/>
		<site site="s_3_1"/>
		<site site="s_4_1"/>
		<site site="s_5_1"/>
		<site site="s_6_1"/>
		<site site="s_7_1"/>
		<site site="s_8_1"/>
		<site site="s_9_1"/>
		<site site="s_10_1"/>
		
		<!-- <site site="s_11_1"/> -->
        </spatial>

		<spatial width="0.002" limited="true" range="0.45 0.55">
		<site site="end_2"/>
		<site site="s_1_2"/>
		<site site="s_2_2"/>
		<site site="s_3_2"/>
		<site site="s_4_2"/>
		<site site="s_5_2"/>
		<site site="s_6_2"/>
		<site site="s_7_2"/>
		<site site="s_8_2"/>
		<site site="s_9_2"/>
		<site site="s_10_2"/>
		
		<!-- <site site="s_11_2"/> -->
        </spatial>


		<spatial width="0.002" limited="true" range="0.45 0.55">
		<site site="end_3"/>
		<site site="s_1_3"/>
		<site site="s_2_3"/>
		<site site="s_3_3"/>
		<site site="s_4_3"/>
		<site site="s_5_3"/>
		<site site="s_6_3"/>
		<site site="s_7_3"/>
		<site site="s_8_3"/>
		<site site="s_9_3"/>
		<site site="s_10_3"/>
		
		<!-- <site site="s_11_3"/> -->
        </spatial>


		<spatial width="0.002" limited="true" range="0.45 0.55">
		<site site="end_4"/>
		<site site="s_1_4"/>
		<site site="s_2_4"/>
		<site site="s_3_4"/>
		<site site="s_4_4"/>
		<site site="s_5_4"/>
		<site site="s_6_4"/>
		<site site="s_7_4"/>
		<site site="s_8_4"/>
		<site site="s_9_4"/>
		<site site="s_10_4"/>
		
		<!-- <site site="s_11_4"/> -->
        </spatial>

		<spatial width="0.002" limited="true" range="0.45 0.55">
		<site site="end_5"/>
		<site site="s_1_5"/>
		<site site="s_2_5"/>
		<site site="s_3_5"/>
		<site site="s_4_5"/>
		<site site="s_5_5"/>
		<site site="s_6_5"/>
		<site site="s_7_5"/>
		<site site="s_8_5"/>
		<site site="s_9_5"/>
		<site site="s_10_5"/>
		
		<!-- <site site="s_11_5"/> -->
        </spatial>


		<spatial width="0.002" limited="true" range="0.45 0.55">
		<site site="end_6"/>
		<site site="s_1_6"/>
		<site site="s_2_6"/>
		<site site="s_3_6"/>
		<site site="s_4_6"/>
		<site site="s_5_6"/>
		<site site="s_6_6"/>
		<site site="s_7_6"/>
		<site site="s_8_6"/>
		<site site="s_9_6"/>
		<site site="s_10_6"/>
		
        </spatial>		
    </tendon>


</mujoco>
